Calling bad()...
exception
ok
Finished bad()
